<?xml version="1.0" encoding="utf-8"?>
<!-- This URDF was automatically created by SolidWorks to URDF Exporter! Originally created by Stephen Brawner (brawner@gmail.com) 
     Commit Version: 1.6.0-4-g7f85cfe  Build Version: 1.6.7995.38578
     For more information, please see http://wiki.ros.org/sw_urdf_exporter -->
<robot
  name="1230URDF">
  <mujoco>
    <compiler meshdir="meshes/" balanceinertia="true" discardvisual="false"/>
  </mujoco>
  <link
    name="base_link">
    <inertial>
      <origin
        xyz="-0.092453 0.000001 -0.034538"
        rpy="0 0 0" />
      <mass
        value="6.466" />
      <inertia
        ixx="0.069712072"
        ixy="-1.60000000E-08"
        ixz="-2.12296000E-04"
        iyy="0.012850718"
        iyz="1.25000000E-07"
        izz="0.06593457" />
    </inertial>
    <visual>
      <origin
        xyz="0 0 0"
        rpy="0 0 0" />
      <geometry>
        <mesh
          filename="./meshes/Robotbase.STL" />
      </geometry>
      <material
        name="">
        <color
          rgba="1 1 1 1" />
      </material>
    </visual>
    <collision>
      <origin
        xyz="0 0 0"
        rpy="0 0 0" />
      <geometry>
        <mesh
          filename="./meshes/Robotbase.STL" />
      </geometry>
    </collision>
  </link>
  <link
    name="left_hip_roll">
    <inertial>
      <origin
        xyz="-0.006182 0 0.007006"
        rpy="0 0 0" />
      <mass
        value="1.819" />
      <inertia
        ixx="0.001948326"
        ixy="3.00000000E-09"
        ixz="7.34910000E-05"
        iyy="0.002083444"
        iyz="4.00000000E-09"
        izz="0.002120683" />
    </inertial>
    <visual>
      <origin
        xyz="0 0 0"
        rpy="0 0 0" />
      <geometry>
        <mesh
          filename="./meshes/left_hip_roll.STL" />
      </geometry>
      <material
        name="">
        <color
          rgba="1 1 1 1" />
      </material>
    </visual>
    <!-- <collision>
      <origin
        xyz="0 0 0"
        rpy="0 0 0" />
      <geometry>
        <mesh
          filename="./meshes/left_hip_roll.STL" />
      </geometry>
    </collision> -->
  </link>
  <joint
    name="left_hip_roll"
    type="revolute">
    <origin
      xyz="0 0.1175 -0.05"
      rpy="0 0 0" />
    <parent
      link="base_link" />
    <child
      link="left_hip_roll" />
    <axis
      xyz="1 0 0" />
    <limit
      lower="-0.175"
      upper="1.047"
      effort="163.000"
      velocity="2.094" />
  </joint>
  <link
    name="left_hip_yaw">
    <inertial>
      <origin
        xyz="-0.009977 0 -0.066373"
        rpy="0 0 0" />
      <mass
        value="0.663" />
      <inertia
        ixx="5.80448000E-04"
        ixy="-3.00000000E-09"
        ixz="6.00350000E-05"
        iyy="5.28970000E-04"
        iyz="-2.00000000E-09"
        izz="6.83307000E-04" />
    </inertial>
    <visual>
      <origin
        xyz="0 0 0"
        rpy="0 0 0" />
      <geometry>
        <mesh
          filename="./meshes/left_hip_yaw.STL" />
      </geometry>
      <material
        name="">
        <color
          rgba="1 1 1 1" />
      </material>
    </visual>
    <!-- <collision>
      <origin
        xyz="0 0 0"
        rpy="0 0 0" />
      <geometry>
        <mesh
          filename="./meshes/left_hip_yaw.STL" />
      </geometry>
    </collision> -->
  </link>
  <joint
    name="left_hip_yaw"
    type="revolute">
    <origin
      xyz="0 0 0"
      rpy="0 0 0" />
    <parent
      link="left_hip_roll" />
    <child
      link="left_hip_yaw" />
    <axis
      xyz="0 0 1" />
    <limit
      lower="-1.047"
      upper="1.047"
      effort="130.000"
      velocity="2.618" />
  </joint>
  <link
    name="left_hip_pitch">
    <inertial>
      <origin
        xyz="0.005188 -0.000188 -0.200716"
        rpy="0 0 0" />
      <mass
        value="10.4965" />
      <inertia
        ixx="0.105361387"
        ixy="2.33780000E-05"
        ixz="-1.04005180E-02"
        iyy="0.127531169"
        iyz="-6.32200000E-06"
        izz="0.038679247" />
    </inertial>
    <visual>
      <origin
        xyz="0 0 0"
        rpy="0 0 0" />
      <geometry>
        <mesh
          filename="./meshes/left_hip_pitch.STL" />
      </geometry>
      <material
        name="">
        <color
          rgba="1 1 1 1" />
      </material>
    </visual>
    <!-- <collision>
      <origin
        xyz="0 0 0"
        rpy="0 0 0" />
      <geometry>
        <mesh
          filename="./meshes/left_hip_pitch.STL" />
      </geometry>
    </collision> -->
  </link>
  <joint
    name="left_hip_pitch"
    type="revolute">
    <origin
      xyz="0 0 -0.077"
      rpy="0 0 0" />
    <parent
      link="left_hip_yaw" />
    <child
      link="left_hip_pitch" />
    <axis
      xyz="0 1 0" />
    <limit
      lower="-1.513"
      upper="0.399"
      effort="484.23"
      velocity="3.926" />
  </joint>
  <link
    name="left_knee_pitch">
    <inertial>
      <origin
        xyz="-0.004126 -0.000001 -0.177064"
        rpy="0 0 0" />
      <mass
        value="4.52604" />
      <inertia
        ixx="0.041051351"
        ixy="-8.40000000E-08"
        ixz="0.005287259"
        iyy="0.039650548"
        iyz="-4.30000000E-07"
        izz="0.011050034" />
    </inertial>
    <visual>
      <origin
        xyz="0 0 0"
        rpy="0 0 0" />
      <geometry>
        <mesh
          filename="./meshes/left_knee_pitch.STL" />
      </geometry>
      <material
        name="">
        <color
          rgba="1 1 1 1" />
      </material>
    </visual>
    <!-- <collision>
      <origin
        xyz="0 0 0"
        rpy="0 0 0" />
      <geometry>
        <mesh
          filename="./meshes/left_knee_pitch.STL" />
      </geometry>
    </collision> -->
  </link>
  <joint
    name="left_knee_pitch"
    type="revolute">
    <origin
      xyz="0 0 -0.385"
      rpy="0 0 0" />
    <parent
      link="left_hip_pitch" />
    <child
      link="left_knee_pitch" />
    <axis
      xyz="0 1 0" />
    <limit
      lower="0.000"
      upper="2.138"
      effort="306.000"
      velocity="2.770" />
  </joint>
  <link
    name="left_ankle_pitch">
    <inertial>
      <origin
        xyz="0.000 0.000 -0.011500"
        rpy="0 0 0" />
      <mass
        value="0.21031" />
      <inertia
        ixx="7.7831E-05"
        ixy="0.000"
        ixz="0.000"
        iyy="7.7831E-05"
        iyz="0.000"
        izz="4.6787E-05" />
    </inertial>
    <visual>
      <origin
        xyz="0 0 0"
        rpy="0 0 0" />
      <geometry>
        <mesh
          filename="./meshes/left_ankle_pitch.STL" />
      </geometry>
      <material
        name="">
        <color
          rgba="1 1 1 1" />
      </material>
    </visual>
    <!-- <collision>
      <origin
        xyz="0 0 0"
        rpy="0 0 0" />
      <geometry>
        <mesh
          filename="./meshes/left_ankle_pitch.STL" />
      </geometry>
    </collision> -->
  </link>
  <joint
    name="left_ankle_pitch"
    type="revolute">
    <origin
      xyz="0 0 -0.385"
      rpy="0 0 0" />
    <parent
      link="left_knee_pitch" />
    <child
      link="left_ankle_pitch" />
    <axis
      xyz="0 1 0" />
    <limit
      lower="-1.047"
      upper="0.349"
      effort="509.163"
      velocity="3.124" />
  </joint>
  <link
    name="left_ankle_roll">
    <inertial>
      <origin
        xyz="0.006747 0.000027 -0.047429"
        rpy="0 0 0" />
      <mass
        value="1.86" />
      <inertia
        ixx="0.002715864"
        ixy="-9.607E-06"
        ixz="-1.063991E-03"
        iyy="0.010561216"
        iyz="-5.29E-07"
        izz="0.010823948" />
    </inertial>
    <visual>
      <origin
        xyz="0 0 0"
        rpy="0 0 0" />
      <geometry>
        <mesh
          filename="./meshes/left_ankle_roll.STL" />
      </geometry>
      <material
        name="">
        <color
          rgba="1 1 1 1" />
      </material>
    </visual>
    <collision>
      <origin
        xyz="0 0 0"
        rpy="0 0 0" />
      <geometry>
        <mesh
          filename="./meshes/left_ankle_roll.STL" />
      </geometry>
    </collision>
  </link>
  <joint
    name="left_ankle_roll"
    type="revolute">
    <origin
      xyz="0 0 -0.023"
      rpy="0 0 0" />
    <parent
      link="left_ankle_pitch" />
    <child
      link="left_ankle_roll" />
    <axis
      xyz="1 0 0" />
    <limit
      lower="-0.436"
      upper="0.436"
      effort="314.930"
      velocity="4.160" />
  </joint>

  <!-- 添加左脚足底的坐标系 -->
  <link name="llegsite">
    <inertial>
      <origin xyz="0 0 0" rpy="0 0 0" />
      <mass value="0.01" />
      <inertia ixx="0" ixy="0" ixz="0" iyy="0" iyz="0" izz="0" />
    </inertial>
  </link>

  <joint name="llegsite_joint" type="fixed">
    <origin xyz="0 0 -0.0795" rpy="0 0 0" />
    <parent link="left_ankle_roll" />
    <child link="llegsite" />
  </joint>

  <link
    name="right_hip_roll">
    <inertial>
      <origin
        xyz="-0.006182 0 0.007006"
        rpy="0 0 0" />
      <mass
        value="1.819" />
      <inertia
        ixx="0.001948326"
        ixy="3.0E-09"
        ixz="7.3491E-05"
        iyy="0.002083444"
        iyz="4.00E-09"
        izz="0.002120683" />
    </inertial>
    <visual>
      <origin
        xyz="0 0 0"
        rpy="0 0 0" />
      <geometry>
        <mesh
          filename="./meshes/right_hip_roll.STL" />
      </geometry>
      <material
        name="">
        <color
          rgba="1 1 1 1" />
      </material>
    </visual>
    <!-- <collision>
      <origin
        xyz="0 0 0"
        rpy="0 0 0" />
      <geometry>
        <mesh
          filename="./meshes/right_hip_roll.STL" />
      </geometry>
    </collision> -->
  </link>
  <joint
    name="right_hip_roll"
    type="revolute">
    <origin
      xyz="0 -0.1175 -0.05"
      rpy="0 0 0" />
    <parent
      link="base_link" />
    <child
      link="right_hip_roll" />
    <axis
      xyz="-1 0 0" />
    <limit
      lower="-0.175"
      upper="1.047"
      effort="163.000"
      velocity="2.094" />
  </joint>
  <link
    name="right_hip_yaw">
    <inertial>
      <origin
        xyz="-0.009977 0 -0.066373"
        rpy="0 0 0" />
      <mass
        value="0.663" />
      <inertia
        ixx="5.80448000E-04"
        ixy="-3.00000000E-09"
        ixz="6.00350000E-05"
        iyy="5.28970000E-04"
        iyz="-2.00000000E-09"
        izz="6.83307000E-04" />
    </inertial>
    <visual>
      <origin
        xyz="0 0 0"
        rpy="0 0 0" />
      <geometry>
        <mesh
          filename="./meshes/right_hip_yaw.STL" />
      </geometry>
      <material
        name="">
        <color
          rgba="1 1 1 1" />
      </material>
    </visual>
    <!-- <collision>
      <origin
        xyz="0 0 0"
        rpy="0 0 0" />
      <geometry>
        <mesh
          filename="./meshes/right_hip_yaw.STL" />
      </geometry>
    </collision> -->
  </link>
  <joint
    name="right_hip_yaw"
    type="revolute">
    <origin
      xyz="0 0 0"
      rpy="0 0 0" />
    <parent
      link="right_hip_roll" />
    <child
      link="right_hip_yaw" />
    <axis
      xyz="0 0 -1" />
    <limit
      lower="-1.047"
      upper="1.047"
      effort="130.000"
      velocity="2.618" />
  </joint>
  <link
    name="right_hip_pitch">
    <inertial>
      <origin
        xyz="0.005189 -0.000191 -0.200708" 
        rpy="0 0 0" />
      <mass
        value="10.4965" />
      <inertia
        ixx="0.10535276"
        ixy="2.3512E-05"
        ixz="-1.0401405E-02"
        iyy="0.127524906"
        iyz="-2.277E-06"
        izz="0.038679697" />
    </inertial>
    <visual>
      <origin
        xyz="0 0 0"
        rpy="0 0 0" />
      <geometry>
        <mesh
          filename="./meshes/right_hip_pitch.STL" />
      </geometry>
      <material
        name="">
        <color
          rgba="1 1 1 1" />
      </material>
    </visual>
    <!-- <collision>
      <origin
        xyz="0 0 0"
        rpy="0 0 0" />
      <geometry>
        <mesh
          filename="./meshes/right_hip_pitch.STL" />
      </geometry>
    </collision> -->
  </link>
  <joint
    name="right_hip_pitch"
    type="revolute">
    <origin
      xyz="0 0 -0.077"
      rpy="0 0 0" />
    <parent
      link="right_hip_yaw" />
    <child
      link="right_hip_pitch" />
    <axis
      xyz="0 1 0" />
    <limit
      lower="-1.513"
      upper="0.399"
      effort="484.23"
      velocity="3.926" />
  </joint>
  <link
    name="right_knee_pitch">
    <inertial>
      <origin
        xyz="-0.004126 -0.000001 -0.177064"
        rpy="0 0 0" />
      <mass
        value="4.52604" />
      <inertia
        ixx="0.041051351"
        ixy="-8.4E-08"
        ixz="0.005287259"
        iyy="0.039650548"
        iyz="-4.3E-07"
        izz="0.011050034" />
    </inertial>
    <visual>
      <origin
        xyz="0 0 0"
        rpy="0 0 0" />
      <geometry>
        <mesh
          filename="./meshes/right_knee_pitch.STL" />
      </geometry>
      <material
        name="">
        <color
          rgba="1 1 1 1" />
      </material>
    </visual>
    <!-- <collision>
      <origin
        xyz="0 0 0"
        rpy="0 0 0" />
      <geometry>
        <mesh
          filename="./meshes/right_knee_pitch.STL" />
      </geometry>
    </collision> -->
  </link>
  <joint
    name="right_knee_pitch"
    type="revolute">
    <origin
      xyz="0 0 -0.385"
      rpy="0 0 0" />
    <parent
      link="right_hip_pitch" />
    <child
      link="right_knee_pitch" />
    <axis
      xyz="0 1 0" />
    <limit
      lower="0.000"
      upper="2.138"
      effort="306.000"
      velocity="2.770" />
  </joint>
  <link
    name="right_ankle_pitch">
    <inertial>
      <origin
        xyz="0.000 0.000 -0.011500"
        rpy="0 0 0" />
      <mass
        value="0.21031" />
      <inertia
        ixx="7.7831E-05"
        ixy="0.000"
        ixz="0.000"
        iyy="7.7831E-05"
        iyz="0.000"
        izz="4.6787E-05" />
    </inertial>
    <visual>
      <origin
        xyz="0 0 0"
        rpy="0 0 0" />
      <geometry>
        <mesh
          filename="./meshes/right_ankle_pitch.STL" />
      </geometry>
      <material
        name="">
        <color
          rgba="1 1 1 1" />
      </material>
    </visual>
    <!-- <collision>
      <origin
        xyz="0 0 0"
        rpy="0 0 0" />
      <geometry>
        <mesh
          filename="./meshes/right_ankle_pitch.STL" />
      </geometry>
    </collision> -->
  </link>
  <joint
    name="right_ankle_pitch"
    type="revolute">
    <origin
      xyz="0 0 -0.385"
      rpy="0 0 0" />
    <parent
      link="right_knee_pitch" />
    <child
      link="right_ankle_pitch" />
    <axis
      xyz="0 1 0" />
    <limit
      lower="-1.047"
      upper="0.349"
      effort="509.163"
      velocity="3.124" />
  </joint>
  <link
    name="right_ankle_roll">
    <inertial>
      <origin
        xyz="0.006747 0.000027 -0.047429"
        rpy="0 0 0" />
      <mass
        value="1.86" />
      <inertia
        ixx="0.002715864"
        ixy="-9.60700000E-06"
        ixz="-1.06399100E-03"
        iyy="0.010561216"
        iyz="-5.29000000E-07"
        izz="0.010823948" />
    </inertial>
    <visual>
      <origin
        xyz="0 0 0"
        rpy="0 0 0" />
      <geometry>
        <mesh
          filename="./meshes/right_ankle_roll.STL" />
      </geometry>
      <material
        name="">
        <color
          rgba="1 1 1 1" />
      </material>
    </visual>
    <collision>
      <origin
        xyz="0 0 0"
        rpy="0 0 0" />
      <geometry>
        <mesh
          filename="./meshes/right_ankle_roll.STL" />
      </geometry>
    </collision>
  </link>
  <joint
    name="right_ankle_roll"
    type="revolute">
    <origin
      xyz="0 0 -0.023"
      rpy="0 0 0" />
    <parent
      link="right_ankle_pitch" />
    <child
      link="right_ankle_roll" />
    <axis
      xyz="-1 0 0" />
    <limit
      lower="-0.436"
      upper="0.436"
      effort="314.930"
      velocity="4.160" />
  </joint>

  <!-- 添加右脚足底的坐标系 -->
  <link name="rlegsite">
    <inertial>
      <origin xyz="0 0 0" rpy="0 0 0" />
      <mass value="0.01" />
      <inertia ixx="0" ixy="0" ixz="0" iyy="0" iyz="0" izz="0" />
    </inertial>
  </link>
  
  <joint name="rlegsite_joint" type="fixed">
    <origin xyz="0 0 -0.0795" rpy="0 0 0" />
    <parent link="right_ankle_roll" />
    <child link="rlegsite" />
  </joint>

  <link
    name="waist_roll">
    <inertial>
      <origin
        xyz="-0.004186 0 -0.006951"
        rpy="0 0 0" />
      <mass
        value="1.815" />
      <inertia
        ixx="0.002180655"
        ixy="-8.00000000E-09"
        ixz="-8.35420000E-05"
        iyy="0.00238951"
        iyz="-3.60000000E-08"
        izz="0.002296057" />
    </inertial>
    <visual>
      <origin
        xyz="0 0 0"
        rpy="0 0 0" />
      <geometry>
        <mesh
          filename="./meshes/waist_roll.STL" />
      </geometry>
      <material
        name="">
        <color
          rgba="1 1 1 1" />
      </material>
    </visual>
    <collision>
      <origin
        xyz="0 0 0"
        rpy="0 0 0" />
      <geometry>
        <mesh
          filename="./meshes/waist_roll.STL" />
      </geometry>
    </collision>
  </link>
  <joint
    name="waist_roll"
    type="revolute">
    <origin
      xyz="0 0 0"
      rpy="0 0 0" />
    <parent
      link="base_link" />
    <child
      link="waist_roll" />
    <axis
      xyz="1 0 0" />
    <limit
      lower="-0.175"
      upper="0.175"
      effort="163.000"
      velocity="2.094" />
  </joint>
  <link
    name="waist_yaw">
    <inertial>
      <origin
        xyz="-0.04269 0.00003 0.24319"
        rpy="0 0 0" />
      <mass
        value="16.823" />
      <inertia
        ixx="0.256789087"
        ixy="-9.02100000E-06"
        ixz="0.007865723"
        iyy="0.21861739"
        iyz="-1.43525000E-04"
        izz="0.122453074" />
    </inertial>
    <visual>
      <origin
        xyz="0 0 0"
        rpy="0 0 0" />
      <geometry>
        <mesh
          filename="./meshes/waist_yaw.STL" />
      </geometry>
      <material
        name="">
        <color
          rgba="1 1 1 1" />
      </material>
    </visual>
    <collision>
      <origin
        xyz="0 0 0"
        rpy="0 0 0" />
      <geometry>
        <mesh
          filename="./meshes/waist_yaw.STL" />
      </geometry>
    </collision>
  </link>
  <joint
    name="waist_yaw"
    type="revolute">
    <origin
      xyz="0 0 0"
      rpy="0 0 0" />
    <parent
      link="waist_roll" />
    <child
      link="waist_yaw" />
    <axis
      xyz="0 0 1" />
    <limit
      lower="-0.785"
      upper="0.785"
      effort="163.000"
      velocity="2.094" />
  </joint>
  <link
    name="head_yaw">
    <inertial>
      <origin
        xyz="0 0.006422 0.0476"
        rpy="0 0 0" />
      <mass
        value="0.43221" />
      <inertia
        ixx="2.57689000E-04"
        ixy="0.0"
        ixz="0.0"
        iyy="2.82335000E-04"
        iyz="9.44100000E-06"
        izz="2.06741000E-04" />
    </inertial>
    <visual>
      <origin
        xyz="0 0 0"
        rpy="0 0 0" />
      <geometry>
        <mesh
          filename="./meshes/head_yaw.STL" />
      </geometry>
      <material
        name="">
        <color
          rgba="1 1 1 1" />
      </material>
    </visual>
    <collision>
      <origin
        xyz="0 0 0"
        rpy="0 0 0" />
      <geometry>
        <mesh
          filename="./meshes/head_yaw.STL" />
      </geometry>
    </collision>
  </link>
  <joint
    name="head_yaw"
    type="revolute">
    <origin
      xyz="-0.020000000000003 0 0.483"
      rpy="0 0 0" />
    <parent
      link="waist_yaw" />
    <child
      link="head_yaw" />
    <axis
      xyz="0 0 -1" />
    <limit
      lower="-0.785"
      upper="0.785"
      effort="29.300"
      velocity="2.094" />
  </joint>
  <link
    name="head_pitch">
    <inertial>
      <origin
        xyz="0.026526 -0.000935 0.090618"
        rpy="0 0 0" />
      <mass
        value="1.19339" />
      <inertia
        ixx="0.007935556"
        ixy="-1.48380000E-05"
        ixz="-8.24006000E-04"
        iyy="0.009109757"
        iyz="8.40370000E-05"
        izz="0.008470691" />
    </inertial>
    <visual>
      <origin
        xyz="0 0 0"
        rpy="0 0 0" />
      <geometry>
        <mesh
          filename="./meshes/head_pitch.STL" />
      </geometry>
      <material
        name="">
        <color
          rgba="1 1 1 1" />
      </material>
    </visual>
    <collision>
      <origin
        xyz="0 0 0"
        rpy="0 0 0" />
      <geometry>
        <mesh
          filename="./meshes/head_pitch.STL" />
      </geometry>
    </collision>
  </link>
  <joint
    name="head_pitch"
    type="revolute">
    <origin
      xyz="0 0 0.0510000000000138"
      rpy="0 0 0" />
    <parent
      link="head_yaw" />
    <child
      link="head_pitch" />
    <axis
      xyz="0 1 0" />
    <limit
      lower="-0.262"
      upper="0.523"
      effort="29.300"
      velocity="2.094" />
  </joint>
  <link
    name="left_shoulder_pitch">
    <inertial>
      <origin
        xyz="-0.000967 0.002123 -0.065723"
        rpy="0 0 0" />
      <mass
        value="1.629" />
      <inertia
        ixx="0.002400607"
        ixy="4.53300000E-06"
        ixz="1.86160000E-05"
        iyy="0.002402184"
        iyz="-5.55000000E-07"
        izz="0.001715245" />
    </inertial>
    <visual>
      <origin
        xyz="0 0 0"
        rpy="0 0 0" />
      <geometry>
        <mesh
          filename="./meshes/left_shoulder_pitch.STL" />
      </geometry>
      <material
        name="">
        <color
          rgba="1 1 1 1" />
      </material>
    </visual>
    <collision>
      <origin
        xyz="0 0 0"
        rpy="0 0 0" />
      <geometry>
        <mesh
          filename="./meshes/left_shoulder_pitch.STL" />
      </geometry>
    </collision>
  </link>
  <joint
    name="left_shoulder_pitch"
    type="revolute">
    <origin
      xyz="-0.0199999999999999 0.13949999999999 0.404"
      rpy="1.5707963267949 0 0" />
    <parent
      link="waist_yaw" />
    <child
      link="left_shoulder_pitch" />
    <axis
      xyz="0 0 1" />
    <limit
      lower="-1.58"
      upper="3.16"
      effort="130"
      velocity="2.62" />
  </joint>
  <link
    name="left_shoulder_roll">
    <inertial>
      <origin
        xyz="0.026227 0.00152 -0.001953"
        rpy="0 0 0" />
      <mass
        value="1.587" />
      <inertia
        ixx="0.002776846"
        ixy="-1.03429000E-04"
        ixz="8.41720000E-05"
        iyy="0.004808973"
        iyz="9.46000000E-07"
        izz="0.004198699" />
    </inertial>
    <visual>
      <origin
        xyz="0 0 0"
        rpy="0 0 0" />
      <geometry>
        <mesh
          filename="./meshes/left_shoulder_roll.STL" />
      </geometry>
      <material
        name="">
        <color
          rgba="1 1 1 1" />
      </material>
    </visual>
    <collision>
      <origin
        xyz="0 0 0"
        rpy="0 0 0" />
      <geometry>
        <mesh
          filename="./meshes/left_shoulder_roll.STL" />
      </geometry>
    </collision>
  </link>
  <joint
    name="left_shoulder_roll"
    type="revolute">
    <origin
      xyz="0 0 -0.077"
      rpy="-1.5707963267949 0 -1.5707963267949" />
    <parent
      link="left_shoulder_pitch" />
    <child
      link="left_shoulder_roll" />
    <axis
      xyz="0 0 1" />
    <limit
      lower="0"
      upper="1.58"
      effort="130"
      velocity="2.62" />
  </joint>
  <link
    name="left_shoulder_yaw">
    <inertial>
      <origin
        xyz="0.000001 0.006031 -0.087644"
        rpy="0 0 0" />
      <mass
        value="1.25" />
      <inertia
        ixx="0.004255287"
        ixy="-9.80000000E-08"
        ixz="-1.25000000E-07"
        iyy="0.004278856"
        iyz="-2.28902000E-04"
        izz="0.001603734" />
    </inertial>
    <visual>
      <origin
        xyz="0 0 0"
        rpy="0 0 0" />
      <geometry>
        <mesh
          filename="./meshes/left_shoulder_yaw.STL" />
      </geometry>
      <material
        name="">
        <color
          rgba="1 1 1 1" />
      </material>
    </visual>
    <collision>
      <origin
        xyz="0 0 0"
        rpy="0 0 0" />
      <geometry>
        <mesh
          filename="./meshes/left_shoulder_yaw.STL" />
      </geometry>
    </collision>
  </link>
  <joint
    name="left_shoulder_yaw"
    type="revolute">
    <origin
      xyz="0.118500000000157 0 0"
      rpy="-1.5707963267949 0 1.5707963267949" />
    <parent
      link="left_shoulder_roll" />
    <child
      link="left_shoulder_yaw" />
    <axis
      xyz="0 0 1" />
    <limit
      lower="-1.58"
      upper="1.58"
      effort="163"
      velocity="2.1" />
  </joint>
  <link
    name="left_elbow_pitch">
    <inertial>
      <origin
        xyz="0.01558 0.036436 -0.000005"
        rpy="0 0 0" />
      <mass
        value="1.064" />
      <inertia
        ixx="0.00124594"
        ixy="3.27260000E-05"
        ixz="-1.20000000E-07"
        iyy="8.74858000E-04"
        iyz="1.90000000E-08"
        izz="0.001140589" />
    </inertial>
    <visual>
      <origin
        xyz="0 0 0"
        rpy="0 0 0" />
      <geometry>
        <mesh
          filename="./meshes/left_elbow_pitch.STL" />
      </geometry>
      <material
        name="">
        <color
          rgba="1 1 1 1" />
      </material>
    </visual>
    <collision>
      <origin
        xyz="0 0 0"
        rpy="0 0 0" />
      <geometry>
        <mesh
          filename="./meshes/left_elbow_pitch.STL" />
      </geometry>
    </collision>
  </link>
  <joint
    name="left_elbow_pitch"
    type="revolute">
    <origin
      xyz="0 -0.00700000000000012 -0.210500002920037"
      rpy="-1.5707963267949 0 1.5707963267949" />
    <parent
      link="left_shoulder_yaw" />
    <child
      link="left_elbow_pitch" />
    <axis
      xyz="0 0 1" />
    <limit
      lower="0"
      upper="2.27"
      effort="60"
      velocity="6.67" />
  </joint>
  <link
    name="left_elbow_yaw">
    <inertial>
      <origin
        xyz="-0.00052 0.005407 -0.062913"
        rpy="0 0 0" />
      <mass
        value="0.969" />
      <inertia
        ixx="0.001612781"
        ixy="3.54500000E-06"
        ixz="1.06500000E-05"
        iyy="0.002250204"
        iyz="-9.20040000E-05"
        izz="0.001315879" />
    </inertial>
    <visual>
      <origin
        xyz="0 0 0"
        rpy="0 0 0" />
      <geometry>
        <mesh
          filename="./meshes/left_elbow_yaw.STL" />
      </geometry>
      <material
        name="">
        <color
          rgba="1 1 1 1" />
      </material>
    </visual>
    <collision>
      <origin
        xyz="0 0 0"
        rpy="0 0 0" />
      <geometry>
        <mesh
          filename="./meshes/left_elbow_yaw.STL" />
      </geometry>
    </collision>
  </link>
  <joint
    name="left_elbow_yaw"
    type="revolute">
    <origin
      xyz="0.0150000000000032 0.0779000084169724 0"
      rpy="-1.57079641267836 0 3.14159265358979" />
    <parent
      link="left_elbow_pitch" />
    <child
      link="left_elbow_yaw" />
    <axis
      xyz="0 0 1" />
    <limit
      lower="-2.1"
      upper="2.1"
      effort="31"
      velocity="2.62" />
  </joint>
  <link
    name="left_wrist_pitch">
    <inertial>
      <origin
        xyz="0.000 -0.004355 0.000"
        rpy="0 0 0" />
      <mass
        value="0.023" />
      <inertia
        ixx="1.819E-06"
        ixy="0.000"
        ixz="0.000"
        iyy="1.224E-06"
        iyz="0.000"
        izz="1.598E-06" />
    </inertial>
    <visual>
      <origin
        xyz="0 0 0"
        rpy="0 0 0" />
      <geometry>
        <mesh
          filename="./meshes/left_wrist_pitch.STL" />
      </geometry>
      <material
        name="">
        <color
          rgba="1 1 1 1" />
      </material>
    </visual>
    <collision>
      <origin
        xyz="0 0 0"
        rpy="0 0 0" />
      <geometry>
        <mesh
          filename="./meshes/left_wrist_pitch.STL" />
      </geometry>
    </collision>
  </link>
  <joint
    name="left_wrist_pitch"
    type="revolute">
    <origin
      xyz="0 0 -0.158"
      rpy="1.5707963267949 0 1.5707963267949" />
    <parent
      link="left_elbow_yaw" />
    <child
      link="left_wrist_pitch" />
    <axis
      xyz="0 0 1" />
    <limit
      lower="-0.7"
      upper="0.35"
      effort="15"
      velocity="3.96" />
  </joint>
  <link
    name="left_wrist_yaw">
    <inertial>
      <origin
        xyz="-0.070305 -0.002637 0.003387"
        rpy="0 0 0" />
      <mass
        value="0.883" />
      <inertia
        ixx="5.75564E-04"
        ixy="3.2923E-05"
        ixz="6.5112E-05"
        iyy="0.001385921"
        iyz="-8.702E-06"
        izz="0.001654264" />
    </inertial>
    <visual>
      <origin
        xyz="0 0 0"
        rpy="0 0 0" />
      <geometry>
        <mesh
          filename="./meshes/left_wrist_yaw.STL" />
      </geometry>
      <material
        name="">
        <color
          rgba="0.89804 0.91765 0.92941 1" />
      </material>
    </visual>
    <collision>
      <origin
        xyz="0 0 0"
        rpy="0 0 0" />
      <geometry>
        <mesh
          filename="./meshes/left_wrist_yaw.STL" />
      </geometry>
    </collision>
  </link>
  <joint
    name="left_wrist_yaw"
    type="revolute">
    <origin
      xyz="0 -0.01 0"
      rpy="-1.5707963267949 0 1.5707963267949" />
    <parent
      link="left_wrist_pitch" />
    <child
      link="left_wrist_yaw" />
    <axis
      xyz="0 0 1" />
    <limit
      lower="-1.31"
      upper="0.96"
      effort="15"
      velocity="10.21" />
  </joint>
  <link
    name="left_thumb_1_roll">
    <inertial>
      <origin
        xyz="-0.000537 0.011649 0.007843"
        rpy="0 0 0" />
      <mass
        value="0.025" />
      <inertia
        ixx="4.776E-06"
        ixy="-5.100E-08"
        ixz="2.900E-08"
        iyy="3.749E-06"
        iyz="4.72E-07"
        izz="2.802E-06" />
    </inertial>
    <visual>
      <origin
        xyz="0 0 0"
        rpy="0 0 0" />
      <geometry>
        <mesh
          filename="./meshes/left_thumb_1_roll.STL" />
      </geometry>
      <material
        name="">
        <color
          rgba="0.89804 0.91765 0.92941 1" />
      </material>
    </visual>
    <collision>
      <origin
        xyz="0 0 0"
        rpy="0 0 0" />
      <geometry>
        <mesh
          filename="./meshes/left_thumb_1_roll.STL" />
      </geometry>
    </collision>
  </link>
  <joint
    name="left_thumb_1_roll"
    type="revolute">
    <origin
      xyz="-0.065711011608865 -0.0355434265047999 0.0304721667720281"
      rpy="3.14159265358979 1.5707963267949 0" />
    <parent
      link="left_wrist_yaw" />
    <child
      link="left_thumb_1_roll" />
    <axis
      xyz="0 0 1" />
    <limit
      lower="0"
      upper="1.75"
      effort="0.5"
      velocity="1.5" />
  </joint>
  <link
    name="left_thumb_2_pitch">
    <inertial>
      <origin
        xyz="-0.01953 -0.006657 0"
        rpy="0 0 0" />
      <mass
        value="0.031" />
      <inertia
        ixx="3.07100000E-06"
        ixy="1.51700000E-06"
        ixz="0.000"
        iyy="6.09800000E-06"
        iyz="0.000"
        izz="6.60000000E-06" />
    </inertial>
    <visual>
      <origin
        xyz="0 0 0"
        rpy="0 0 0" />
      <geometry>
        <mesh
          filename="./meshes/left_thumb_2_pitch.STL" />
      </geometry>
      <material
        name="">
        <color
          rgba="1 1 1 1" />
      </material>
    </visual>
    <collision>
      <origin
        xyz="0 0 0"
        rpy="0 0 0" />
      <geometry>
        <mesh
          filename="./meshes/left_thumb_2_pitch.STL" />
      </geometry>
    </collision>
  </link>
  <joint
    name="left_thumb_2_pitch"
    type="revolute">
    <origin
      xyz="0 0.0240000000043515 0.0191499999674365"
      rpy="-1.5707963267949 0 -1.5707963267949" />
    <parent
      link="left_thumb_1_roll" />
    <child
      link="left_thumb_2_pitch" />
    <axis
      xyz="0 0 1" />
    <limit
      lower="0"
      upper="1.58"
      effort="0.5"
      velocity="1.5" />
  </joint>
  <link
    name="left_thumb_3_pitch">
    <inertial>
      <origin
        xyz="-0.022652 -0.010625 0.000"
        rpy="0 0 0" />
      <mass
        value="0.0226" />
      <inertia
        ixx="2.02300000E-06"
        ixy="1.58500000E-06"
        ixz="0.000"
        iyy="3.68200000E-06"
        iyz="0.000"
        izz="4.55500000E-06" />
    </inertial>
    <visual>
      <origin
        xyz="0 0 0"
        rpy="0 0 0" />
      <geometry>
        <mesh
          filename="./meshes/left_thumb_3_pitch.STL" />
      </geometry>
      <material
        name="">
        <color
          rgba="1 1 1 1" />
      </material>
    </visual>
    <collision>
      <origin
        xyz="0 0 0"
        rpy="0 0 0" />
      <geometry>
        <mesh
          filename="./meshes/left_thumb_3_pitch.STL" />
      </geometry>
    </collision>
  </link>
  <joint
    name="left_thumb_3_pitch"
    type="revolute">
    <origin
      xyz="-0.0394670900730081 -0.0143648460196782 0"
      rpy="0 0 0" />
    <parent
      link="left_thumb_2_pitch" />
    <child
      link="left_thumb_3_pitch" />
    <axis
      xyz="0 0 1" />
    <limit
      lower="0"
      upper="1.58"
      effort="0.5"
      velocity="1.5" />
  </joint>
  <link
    name="left_index_finger_2_pitch">
    <inertial>
      <origin
        xyz="0.000424 -0.020629 0"
        rpy="0 0 0" />
      <mass
        value="0.0308" />
      <inertia
        ixx="6.719E-06"
        ixy="1.89E-07"
        ixz="0.000"
        iyy="2.45E-06"
        iyz="0.000"
        izz="6.6E-06" />
    </inertial>
    <visual>
      <origin
        xyz="0 0 0"
        rpy="0 0 0" />
      <geometry>
        <mesh
          filename="./meshes/left_index_finger_2_pitch.STL" />
      </geometry>
      <material
        name="">
        <color
          rgba="1 1 1 1" />
      </material>
    </visual>
    <collision>
      <origin
        xyz="0 0 0"
        rpy="0 0 0" />
      <geometry>
        <mesh
          filename="./meshes/left_index_finger_2_pitch.STL" />
      </geometry>
    </collision>
  </link>
  <joint
    name="left_index_finger_2_pitch"
    type="revolute">
    <origin
      xyz="-0.149999999987412 -0.0355434264207067 -0.00354780308283045"
      rpy="-3.13755534197538 1.57079580738735 1.57483363840931" />
    <parent
      link="left_wrist_yaw" />
    <child
      link="left_index_finger_2_pitch" />
    <axis
      xyz="0 0 -1" />
    <limit
      lower="0"
      upper="1.58"
      effort="0.5"
      velocity="1.5" />
  </joint>
  <link
    name="left_index_finger_3_pitch">
    <inertial>
      <origin
        xyz="-0.002405 -0.021599 0"
        rpy="0 0 0" />
      <mass
        value="0.0189" />
      <inertia
        ixx="2.967E-06"
        ixy="6.44E-07"
        ixz="0.000"
        iyy="1.024E-06"
        iyz="0.000"
        izz="3.127E-06" />
    </inertial>
    <visual>
      <origin
        xyz="0 0 0"
        rpy="0 0 0" />
      <geometry>
        <mesh
          filename="./meshes/left_index_finger_3_pitch.STL" />
      </geometry>
      <material
        name="">
        <color
          rgba="1 1 1 1" />
      </material>
    </visual>
    <collision>
      <origin
        xyz="0 0 0"
        rpy="0 0 0" />
      <geometry>
        <mesh
          filename="./meshes/left_index_finger_3_pitch.STL" />
      </geometry>
    </collision>
  </link>
  <joint
    name="left_index_finger_3_pitch"
    type="revolute">
    <origin
      xyz="0 -0.0419999999936377 0"
      rpy="0 0 0" />
    <parent
      link="left_index_finger_2_pitch" />
    <child
      link="left_index_finger_3_pitch" />
    <axis
      xyz="0 0 -1" />
    <limit
      lower="0"
      upper="1.58"
      effort="0.5"
      velocity="1.5" />
  </joint>
  <link
    name="left_middle_finger_2_pitch">
    <inertial>
      <origin
        xyz="0.000424 -0.020629 0"
        rpy="0 0 0" />
      <mass
        value="0.0308" />
      <inertia
        ixx="6.71900000E-06"
        ixy="1.89000000E-07"
        ixz="0.000"
        iyy="2.45000000E-06"
        iyz="0.000"
        izz="6.60000000E-06" />
    </inertial>
    <visual>
      <origin
        xyz="0 0 0"
        rpy="0 0 0" />
      <geometry>
        <mesh
          filename="./meshes/left_middle_finger_2_pitch.STL" />
      </geometry>
      <material
        name="">
        <color
          rgba="1 1 1 1" />
      </material>
    </visual>
    <collision>
      <origin
        xyz="0 0 0"
        rpy="0 0 0" />
      <geometry>
        <mesh
          filename="./meshes/left_middle_finger_2_pitch.STL" />
      </geometry>
    </collision>
  </link>
  <joint
    name="left_middle_finger_2_pitch"
    type="revolute">
    <origin
      xyz="-0.152 -0.012043425641428 -0.00504725373861389"
      rpy="-3.14159265264672 1.57079580738735 1.57079632773797" />
    <parent
      link="left_wrist_yaw" />
    <child
      link="left_middle_finger_2_pitch" />
    <axis
      xyz="0 0 -1" />
    <limit
      lower="0"
      upper="1.58"
      effort="0.5"
      velocity="1.5" />
  </joint>
  <link
    name="left_middle_finger_3_pitch">
    <inertial>
      <origin
        xyz="-0.002405 -0.021599 0"
        rpy="0 0 0" />
      <mass
        value="0.0189" />
      <inertia
        ixx="2.96700000E-06"
        ixy="6.44000000E-07"
        ixz="0.000"
        iyy="1.02400000E-06"
        iyz="0.000"
        izz="3.12700000E-06" />
    </inertial>
    <visual>
      <origin
        xyz="0 0 0"
        rpy="0 0 0" />
      <geometry>
        <mesh
          filename="./meshes/left_middle_finger_3_pitch.STL" />
      </geometry>
      <material
        name="">
        <color
          rgba="1 1 1 1" />
      </material>
    </visual>
    <collision>
      <origin
        xyz="0 0 0"
        rpy="0 0 0" />
      <geometry>
        <mesh
          filename="./meshes/left_middle_finger_3_pitch.STL" />
      </geometry>
    </collision>
  </link>
  <joint
    name="left_middle_finger_3_pitch"
    type="revolute">
    <origin
      xyz="0 -0.042 0"
      rpy="0 0 0" />
    <parent
      link="left_middle_finger_2_pitch" />
    <child
      link="left_middle_finger_3_pitch" />
    <axis
      xyz="0 0 -1" />
    <limit
      lower="0"
      upper="1.58"
      effort="0.5"
      velocity="1.5" />
  </joint>
  <link
    name="left_ring_finger_2_pitch">
    <inertial>
      <origin
        xyz="0.000424 -0.020629 0"
        rpy="0 0 0" />
      <mass
        value="0.0308" />
      <inertia
        ixx="6.71900000E-06"
        ixy="1.89000000E-07"
        ixz="0.000"
        iyy="2.45000000E-06"
        iyz="0.000"
        izz="6.60000000E-06" />
    </inertial>
    <visual>
      <origin
        xyz="0 0 0"
        rpy="0 0 0" />
      <geometry>
        <mesh
          filename="./meshes/left_ring_finger_2_pitch.STL" />
      </geometry>
      <material
        name="">
        <color
          rgba="1 1 1 1" />
      </material>
    </visual>
    <collision>
      <origin
        xyz="0 0 0"
        rpy="0 0 0" />
      <geometry>
        <mesh
          filename="./meshes/left_ring_finger_2_pitch.STL" />
      </geometry>
    </collision>
  </link>
  <joint
    name="left_ring_finger_2_pitch"
    type="revolute">
    <origin
      xyz="-0.149634612145833 0.0112889946629825 -0.00354621663087695"
      rpy="-3.03018290397524 1.57071101857885 1.64729959342517" />
    <parent
      link="left_wrist_yaw" />
    <child
      link="left_ring_finger_2_pitch" />
    <axis
      xyz="0 0 -1" />
    <limit
      lower="0"
      upper="1.58"
      effort="0.5"
      velocity="1.5" />
  </joint>
  <link
    name="left_ring_finger_3_pitch">
    <inertial>
      <origin
        xyz="-0.002405 -0.021599 0"
        rpy="0 0 0" />
      <mass
        value="0.0189" />
      <inertia
        ixx="2.96700000E-06"
        ixy="6.44000000E-07"
        ixz="0.000"
        iyy="1.02400000E-06"
        iyz="0.000"
        izz="3.12700000E-06" />
    </inertial>
    <visual>
      <origin
        xyz="0 0 0"
        rpy="0 0 0" />
      <geometry>
        <mesh
          filename="./meshes/left_ring_finger_3_pitch.STL" />
      </geometry>
      <material
        name="">
        <color
          rgba="1 1 1 1" />
      </material>
    </visual>
    <collision>
      <origin
        xyz="0 0 0"
        rpy="0 0 0" />
      <geometry>
        <mesh
          filename="./meshes/left_ring_finger_3_pitch.STL" />
      </geometry>
    </collision>
  </link>
  <joint
    name="left_ring_finger_3_pitch"
    type="revolute">
    <origin
      xyz="0 -0.0420000000000142 0"
      rpy="0 0 0" />
    <parent
      link="left_ring_finger_2_pitch" />
    <child
      link="left_ring_finger_3_pitch" />
    <axis
      xyz="0 0 -1" />
    <limit
      lower="0"
      upper="1.58"
      effort="0.5"
      velocity="1.5" />
  </joint>
  <link
    name="left_little_finger_2_pitch">
    <inertial>
      <origin
        xyz="0.000424 -0.020629 0"
        rpy="0 0 0" />
      <mass
        value="0.0308" />
      <inertia
        ixx="6.71900000E-06"
        ixy="1.89000000E-07"
        ixz="0.000"
        iyy="2.45000000E-06"
        iyz="0.000"
        izz="6.60000000E-06" />
    </inertial>
    <visual>
      <origin
        xyz="0 0 0"
        rpy="0 0 0" />
      <geometry>
        <mesh
          filename="./meshes/left_little_finger_2_pitch.STL" />
      </geometry>
      <material
        name="">
        <color
          rgba="1 1 1 1" />
      </material>
    </visual>
    <collision>
      <origin
        xyz="0 0 0"
        rpy="0 0 0" />
      <geometry>
        <mesh
          filename="./meshes/left_little_finger_2_pitch.STL" />
      </geometry>
    </collision>
  </link>
  <joint
    name="left_little_finger_2_pitch"
    type="revolute">
    <origin
      xyz="-0.146952858031617 0.0346341052013608 -0.00329321698308266"
      rpy="3.1415926535425 1.57079580717365 1.50098315666782" />
    <parent
      link="left_wrist_yaw" />
    <child
      link="left_little_finger_2_pitch" />
    <axis
      xyz="0 0 -1" />
    <limit
      lower="0"
      upper="1.58"
      effort="0.5"
      velocity="1.5" />
  </joint>
  <link
    name="left_little_finger_3_pitch">
    <inertial>
      <origin
        xyz="-0.002405 -0.021599 0"
        rpy="0 0 0" />
      <mass
        value="0.0189" />
      <inertia
        ixx="2.96700000E-06"
        ixy="6.44000000E-07"
        ixz="0.000"
        iyy="1.02400000E-06"
        iyz="0.000"
        izz="3.12700000E-06" />
    </inertial>
    <visual>
      <origin
        xyz="0 0 0"
        rpy="0 0 0" />
      <geometry>
        <mesh
          filename="./meshes/left_little_finger_3_pitch.STL" />
      </geometry>
      <material
        name="">
        <color
          rgba="1 1 1 1" />
      </material>
    </visual>
    <collision>
      <origin
        xyz="0 0 0"
        rpy="0 0 0" />
      <geometry>
        <mesh
          filename="./meshes/left_little_finger_3_pitch.STL" />
      </geometry>
    </collision>
  </link>
  <joint
    name="left_little_finger_3_pitch"
    type="revolute">
    <origin
      xyz="0 -0.042 0"
      rpy="0 0 0" />
    <parent
      link="left_little_finger_2_pitch" />
    <child
      link="left_little_finger_3_pitch" />
    <axis
      xyz="0 0 -1" />
    <limit
      lower="0"
      upper="1.58"
      effort="0.5"
      velocity="1.5" />
  </joint>
  <link
    name="right_shoulder_pitch">
    <inertial>
      <origin
        xyz="-0.000967 0.002123 0.065723"
        rpy="0 0 0" />
      <mass
        value="1.629" />
      <inertia
        ixx="0.00240062"
        ixy="4.52300000E-06"
        ixz="-1.86140000E-05"
        iyy="0.002402194"
        iyz="5.47000000E-07"
        izz="0.001715235" />
    </inertial>
    <visual>
      <origin
        xyz="0 0 0"
        rpy="0 0 0" />
      <geometry>
        <mesh
          filename="./meshes/right_shoulder_pitch.STL" />
      </geometry>
      <material
        name="">
        <color
          rgba="1 1 1 1" />
      </material>
    </visual>
    <collision>
      <origin
        xyz="0 0 0"
        rpy="0 0 0" />
      <geometry>
        <mesh
          filename="./meshes/right_shoulder_pitch.STL" />
      </geometry>
    </collision>
  </link>
  <joint
    name="right_shoulder_pitch"
    type="revolute">
    <origin
      xyz="-0.0199999999999999 -0.13949999999999 0.404"
      rpy="1.5707963267949 0 0" />
    <parent
      link="waist_yaw" />
    <child
      link="right_shoulder_pitch" />
    <axis
      xyz="0 0 1" />
    <limit
      lower="-1.58"
      upper="3.16"
      effort="130"
      velocity="2.62" />
  </joint>
  <link
    name="right_shoulder_roll">
    <inertial>
      <origin
        xyz="0.026226 0.001521 0.001953"
        rpy="0 0 0" />
      <mass
        value="1.587" />
      <inertia
        ixx="0.002776752"
        ixy="-1.03338000E-04"
        ixz="-8.41630000E-05"
        iyy="0.004808881"
        iyz="-8.84000000E-07"
        izz="0.004198481" />
    </inertial>
    <visual>
      <origin
        xyz="0 0 0"
        rpy="0 0 0" />
      <geometry>
        <mesh
          filename="./meshes/right_shoulder_roll.STL" />
      </geometry>
      <material
        name="">
        <color
          rgba="1 1 1 1" />
      </material>
    </visual>
    <collision>
      <origin
        xyz="0 0 0"
        rpy="0 0 0" />
      <geometry>
        <mesh
          filename="./meshes/right_shoulder_roll.STL" />
      </geometry>
    </collision>
  </link>
  <joint
    name="right_shoulder_roll"
    type="revolute">
    <origin
      xyz="0 0 0.077"
      rpy="1.5707963267949 0 -1.5707963267949" />
    <parent
      link="right_shoulder_pitch" />
    <child
      link="right_shoulder_roll" />
    <axis
      xyz="0 0 1" />
    <limit
      lower="0"
      upper="1.58"
      effort="130"
      velocity="2.62" />
  </joint>
  <link
    name="right_shoulder_yaw">
    <inertial>
      <origin
        xyz="0.000001 -0.006031 0.087644"
        rpy="0 0 0" />
      <mass
        value="1.25" />
      <inertia
        ixx="0.004255287"
        ixy="9.80000000E-08"
        ixz="1.26000000E-07"
        iyy="0.004278856"
        iyz="-2.28902000E-04"
        izz="0.001603734" />
    </inertial>
    <visual>
      <origin
        xyz="0 0 0"
        rpy="0 0 0" />
      <geometry>
        <mesh
          filename="./meshes/right_shoulder_yaw.STL" />
      </geometry>
      <material
        name="">
        <color
          rgba="1 1 1 1" />
      </material>
    </visual>
    <collision>
      <origin
        xyz="0 0 0"
        rpy="0 0 0" />
      <geometry>
        <mesh
          filename="./meshes/right_shoulder_yaw.STL" />
      </geometry>
    </collision>
  </link>
  <joint
    name="right_shoulder_yaw"
    type="revolute">
    <origin
      xyz="0.118500000000157 0 0"
      rpy="-1.5707963267949 0 -1.5707963267949" />
    <parent
      link="right_shoulder_roll" />
    <child
      link="right_shoulder_yaw" />
    <axis
      xyz="0 0 1" />
    <limit
      lower="-1.58"
      upper="1.58"
      effort="163"
      velocity="2.1" />
  </joint>
  <link
    name="right_elbow_pitch">
    <inertial>
      <origin
        xyz="0.01558 0.036436 -0.000005"
        rpy="0 0 0" />
      <mass
        value="1.064" />
      <inertia
        ixx="0.00124594"
        ixy="3.27260000E-05"
        ixz="-1.20000000E-07"
        iyy="8.74858000E-04"
        iyz="1.90000000E-08"
        izz="0.001140589" />
    </inertial>
    <visual>
      <origin
        xyz="0 0 0"
        rpy="0 0 0" />
      <geometry>
        <mesh
          filename="./meshes/right_elbow_pitch.STL" />
      </geometry>
      <material
        name="">
        <color
          rgba="1 1 1 1" />
      </material>
    </visual>
    <collision>
      <origin
        xyz="0 0 0"
        rpy="0 0 0" />
      <geometry>
        <mesh
          filename="./meshes/right_elbow_pitch.STL" />
      </geometry>
    </collision>
  </link>
  <joint
    name="right_elbow_pitch"
    type="revolute">
    <origin
      xyz="0 0.00700000000000011 0.210500002920037"
      rpy="1.57079624091144 0 -1.5707963267949" />
    <parent
      link="right_shoulder_yaw" />
    <child
      link="right_elbow_pitch" />
    <axis
      xyz="0 0 1" />
    <limit
      lower="0"
      upper="2.27"
      effort="60"
      velocity="6.67" />
  </joint>
  <link
    name="right_elbow_yaw">
    <inertial>
      <origin
        xyz="0.000525 -0.005407 0.068814"
        rpy="0 0 0" />
      <mass
        value="0.969" />
      <inertia
        ixx="0.001612882"
        ixy="3.28100000E-06"
        ixz="1.10300000E-05"
        iyy="0.002250348"
        iyz="-9.20090000E-05"
        izz="0.001315961" />
    </inertial>
    <visual>
      <origin
        xyz="0 0 0"
        rpy="0 0 0" />
      <geometry>
        <mesh
          filename="./meshes/right_elbow_yaw.STL" />
      </geometry>
      <material
        name="">
        <color
          rgba="1 1 1 1" />
      </material>
    </visual>
    <collision>
      <origin
        xyz="0 0 0"
        rpy="0 0 0" />
      <geometry>
        <mesh
          filename="./meshes/right_elbow_yaw.STL" />
      </geometry>
    </collision>
  </link>
  <joint
    name="right_elbow_yaw"
    type="revolute">
    <origin
      xyz="0.0150000000000032 0.0719999970799724 0"
      rpy="-1.5707963267949 0 0" />
    <parent
      link="right_elbow_pitch" />
    <child
      link="right_elbow_yaw" />
    <axis
      xyz="0 0 -1" />
    <limit
      lower="-2.1"
      upper="2.1"
      effort="31"
      velocity="2.62" />
  </joint>
  <link
    name="right_wrist_pitch">
    <inertial>
      <origin
        xyz="0.000 0.004355 0.000"
        rpy="0 0 0" />
      <mass
        value="0.023" />
      <inertia
        ixx="1.819E-06"
        ixy="0.000"
        ixz="0.000"
        iyy="1.224E-06"
        iyz="0.000"
        izz="1.598E-06" />
    </inertial>
    <visual>
      <origin
        xyz="0 0 0"
        rpy="0 0 0" />
      <geometry>
        <mesh
          filename="./meshes/right_wrist_pitch.STL" />
      </geometry>
      <material
        name="">
        <color
          rgba="1 1 1 1" />
      </material>
    </visual>
    <collision>
      <origin
        xyz="0 0 0"
        rpy="0 0 0" />
      <geometry>
        <mesh
          filename="./meshes/right_wrist_pitch.STL" />
      </geometry>
    </collision>
  </link>
  <joint
    name="right_wrist_pitch"
    type="revolute">
    <origin
      xyz="0 0 0.163900011337"
      rpy="1.5707963267949 0 1.5707963267949" />
    <parent
      link="right_elbow_yaw" />
    <child
      link="right_wrist_pitch" />
    <axis
      xyz="0 0 1" />
    <limit
      lower="-0.7"
      upper="0.35"
      effort="15"
      velocity="3.96" />
  </joint>
  <link
    name="right_wrist_yaw">
    <inertial>
      <origin
        xyz="0.002637 -0.070305 -0.003387"
        rpy="0 0 1.5708" />
      <mass
        value="0.883" />
      <inertia
        ixx="5.75504E-04"
        ixy="3.3074E-05"
        ixz="-6.5114E-05"
        iyy="0.001386001"
        iyz="8.639E-06"
        izz="0.001654265" />
    </inertial>
    <visual>
      <origin
        xyz="0 0 0"
        rpy="0 0 1.5708" />
      <geometry>
        <mesh
          filename="./meshes/right_wrist_yaw.STL" />
      </geometry>
      <material
        name="">
        <color
          rgba="0.86667 0.86667 0.8902 1" />
      </material>
    </visual>
    <collision>
      <origin
        xyz="0 0 0"
        rpy="0 0 1.5708" />
      <geometry>
        <mesh
          filename="./meshes/right_wrist_yaw.STL" />
      </geometry>
    </collision>
  </link>
  <joint
    name="right_wrist_yaw"
    type="revolute">
    <origin
      xyz="0 0.01 0"
      rpy="3.14159265358979 1.5707963267949 0" />
    <parent
      link="right_wrist_pitch" />
    <child
      link="right_wrist_yaw" />
    <axis
      xyz="0 0 1" />
    <limit
      lower="-1.31"
      upper="0.96"
      effort="15"
      velocity="10.21" />
  </joint>
  <link
    name="right_thumb_1_roll">
    <inertial>
      <origin
        xyz="0.000503 -0.011994 -0.007120"
        rpy="0 0 0" />
      <mass
        value="0.025" />
      <inertia
        ixx="4.561E-06"
        ixy="5.300E-08"
        ixz="-3.100E-08"
        iyy="3.611E-06"
        iyz="3.91E-07"
        izz="2.652E-06" />
    </inertial>
    <visual>
      <origin
        xyz="0 0 0"
        rpy="0 0 0" />
      <geometry>
        <mesh
          filename="./meshes/right_thumb_1_roll.STL" />
      </geometry>
      <material
        name="">
        <color
          rgba="1 1 1 1" />
      </material>
    </visual>
    <collision>
      <origin
        xyz="0 0 0"
        rpy="0 0 0" />
      <geometry>
        <mesh
          filename="./meshes/right_thumb_1_roll.STL" />
      </geometry>
    </collision>
  </link>
  <joint
    name="right_thumb_1_roll"
    type="revolute">
    <origin
      xyz="0.0355434265047999 -0.065711011608865 -0.030472166772028"
      rpy="1.5707963267949 1.5707963267949 0" />
    <parent
      link="right_wrist_yaw" />
    <child
      link="right_thumb_1_roll" />
    <axis
      xyz="0 0 1" />
    <limit
      lower="0"
      upper="1.75"
      effort="0.5"
      velocity="1.5" />
  </joint>
  <link
    name="right_thumb_2_pitch">
    <inertial>
      <origin
        xyz="-0.019570 0.006657 0"
        rpy="0 0 0" />
      <mass
        value="0.031" />
      <inertia
        ixx="3.07100000E-06"
        ixy="-1.51700000E-06"
        ixz="0.000"
        iyy="6.09800000E-06"
        iyz="0.000"
        izz="6.60000000E-06" />
    </inertial>
    <visual>
      <origin
        xyz="0 0 0"
        rpy="0 0 0" />
      <geometry>
        <mesh
          filename="./meshes/right_thumb_2_pitch.STL" />
      </geometry>
      <material
        name="">
        <color
          rgba="1 1 1 1" />
      </material>
    </visual>
    <collision>
      <origin
        xyz="0 0 0"
        rpy="0 0 0" />
      <geometry>
        <mesh
          filename="./meshes/right_thumb_2_pitch.STL" />
      </geometry>
    </collision>
  </link>
  <joint
    name="right_thumb_2_pitch"
    type="revolute">
    <origin
      xyz="0 0.0240000010235686 0.019149997148431"
      rpy="1.5707963267949 0 -1.5707963267949" />
    <parent
      link="right_thumb_1_roll" />
    <child
      link="right_thumb_2_pitch" />
    <axis
      xyz="0 0 -1" />
    <limit
      lower="0"
      upper="1.58"
      effort="0.5"
      velocity="1.5" />
  </joint>
  <link
    name="right_thumb_3_pitch">
    <inertial>
      <origin
        xyz="-0.022652 0.010625 0.000"
        rpy="0 0 0" />
      <mass
        value="0.0226" />
      <inertia
        ixx="2.02300000E-06"
        ixy="-1.58500000E-06"
        ixz="0.000"
        iyy="3.68200000E-06"
        iyz="0.000"
        izz="4.55500000E-06" />
    </inertial>
    <visual>
      <origin
        xyz="0 0 0"
        rpy="0 0 0" />
      <geometry>
        <mesh
          filename="./meshes/right_thumb_3_pitch.STL" />
      </geometry>
      <material
        name="">
        <color
          rgba="1 1 1 1" />
      </material>
    </visual>
    <collision>
      <origin
        xyz="0 0 0"
        rpy="0 0 0" />
      <geometry>
        <mesh
          filename="./meshes/right_thumb_3_pitch.STL" />
      </geometry>
    </collision>
  </link>
  <joint
    name="right_thumb_3_pitch"
    type="revolute">
    <origin
      xyz="-0.039467089053791 0.0143648488386837 0"
      rpy="0 0 0" />
    <parent
      link="right_thumb_2_pitch" />
    <child
      link="right_thumb_3_pitch" />
    <axis
      xyz="0 0 -1" />
    <limit
      lower="0"
      upper="1.58"
      effort="0.5"
      velocity="1.5" />
  </joint>
  <link
    name="right_index_finger_2_pitch">
    <inertial>
      <origin
        xyz="-0.000424 0.020629 0"
        rpy="0 0 0" />
      <mass
        value="0.0308" />
      <inertia
        ixx="6.71900000E-06"
        ixy="1.89000000E-07"
        ixz="0.000"
        iyy="2.45000000E-06"
        iyz="0.000"
        izz="6.60000000E-06" />
    </inertial>
    <visual>
      <origin
        xyz="0 0 0"
        rpy="0 0 0" />
      <geometry>
        <mesh
          filename="./meshes/right_index_finger_2_pitch.STL" />
      </geometry>
      <material
        name="">
        <color
          rgba="1 1 1 1" />
      </material>
    </visual>
    <collision>
      <origin
        xyz="0 0 0"
        rpy="0 0 0" />
      <geometry>
        <mesh
          filename="./meshes/right_index_finger_2_pitch.STL" />
      </geometry>
    </collision>
  </link>
  <joint
    name="right_index_finger_2_pitch"
    type="revolute">
    <origin
      xyz="0.0355434264207082 -0.149999999987412 0.00354779996458673"
      rpy="-3.13755534346985 1.57079580717365 0.00403731011994333" />
    <parent
      link="right_wrist_yaw" />
    <child
      link="right_index_finger_2_pitch" />
    <axis
      xyz="0 0 -1" />
    <limit
      lower="0"
      upper="1.58"
      effort="0.5"
      velocity="1.5" />
  </joint>
  <link
    name="right_index_finger_3_pitch">
    <inertial>
      <origin
        xyz="0.002405 0.021599 0"
        rpy="0 0 0" />
      <mass
        value="0.0189" />
      <inertia
        ixx="2.96700000E-06"
        ixy="6.44000000E-07"
        ixz="0.000"
        iyy="1.02400000E-06"
        iyz="0.000"
        izz="3.12700000E-06" />
    </inertial>
    <visual>
      <origin
        xyz="0 0 0"
        rpy="0 0 0" />
      <geometry>
        <mesh
          filename="./meshes/right_index_finger_3_pitch.STL" />
      </geometry>
      <material
        name="">
        <color
          rgba="1 1 1 1" />
      </material>
    </visual>
    <collision>
      <origin
        xyz="0 0 0"
        rpy="0 0 0" />
      <geometry>
        <mesh
          filename="./meshes/right_index_finger_3_pitch.STL" />
      </geometry>
    </collision>
  </link>
  <joint
    name="right_index_finger_3_pitch"
    type="revolute">
    <origin
      xyz="0 0.0419999999999999 0"
      rpy="0 0 0" />
    <parent
      link="right_index_finger_2_pitch" />
    <child
      link="right_index_finger_3_pitch" />
    <axis
      xyz="0 0 -1" />
    <limit
      lower="0"
      upper="1.58"
      effort="0.5"
      velocity="1.5" />
  </joint>
  <link
    name="right_middle_finger_2_pitch">
    <inertial>
      <origin
        xyz="-0.000424 0.020629 0"
        rpy="0 0 0" />
      <mass
        value="0.0308" />
      <inertia
        ixx="6.71900000E-06"
        ixy="1.89000000E-07"
        ixz="0.000"
        iyy="2.45000000E-06"
        iyz="0.000"
        izz="6.60000000E-06" />
    </inertial>
    <visual>
      <origin
        xyz="0 0 0"
        rpy="0 0 0" />
      <geometry>
        <mesh
          filename="./meshes/right_middle_finger_2_pitch.STL" />
      </geometry>
      <material
        name="">
        <color
          rgba="1 1 1 1" />
      </material>
    </visual>
    <collision>
      <origin
        xyz="0 0 0"
        rpy="0 0 0" />
      <geometry>
        <mesh
          filename="./meshes/right_middle_finger_2_pitch.STL" />
      </geometry>
    </collision>
  </link>
  <joint
    name="right_middle_finger_2_pitch"
    type="revolute">
    <origin
      xyz="0.0120434256414312 -0.152 0.00504724750212629"
      rpy="3.14159265304057 1.57079580717365 0" />
    <parent
      link="right_wrist_yaw" />
    <child
      link="right_middle_finger_2_pitch" />
    <axis
      xyz="0 0 -1" />
    <limit
      lower="0"
      upper="1.58"
      effort="0.5"
      velocity="1.5" />
  </joint>
  <link
    name="right_middle_finger_3_pitch">
    <inertial>
      <origin
        xyz="0.002405 0.021599 0"
        rpy="0 0 0" />
      <mass
        value="0.0189" />
      <inertia
        ixx="2.96700000E-06"
        ixy="6.44000000E-07"
        ixz="0.000"
        iyy="1.02400000E-06"
        iyz="0.000"
        izz="3.12700000E-06" />
    </inertial>
    <visual>
      <origin
        xyz="0 0 0"
        rpy="0 0 0" />
      <geometry>
        <mesh
          filename="./meshes/right_middle_finger_3_pitch.STL" />
      </geometry>
      <material
        name="">
        <color
          rgba="1 1 1 1" />
      </material>
    </visual>
    <collision>
      <origin
        xyz="0 0 0"
        rpy="0 0 0" />
      <geometry>
        <mesh
          filename="./meshes/right_middle_finger_3_pitch.STL" />
      </geometry>
    </collision>
  </link>
  <joint
    name="right_middle_finger_3_pitch"
    type="revolute">
    <origin
      xyz="0 0.042 0"
      rpy="0 0 0" />
    <parent
      link="right_middle_finger_2_pitch" />
    <child
      link="right_middle_finger_3_pitch" />
    <axis
      xyz="0 0 -1" />
    <limit
      lower="0"
      upper="1.58"
      effort="0.5"
      velocity="1.5" />
  </joint>
  <link
    name="right_ring_finger_2_pitch">
    <inertial>
      <origin
        xyz="-0.000424 0.020629 0"
        rpy="0 0 0" />
      <mass
        value="0.0308" />
      <inertia
        ixx="6.71900000E-06"
        ixy="1.89000000E-07"
        ixz="0.000"
        iyy="2.45000000E-06"
        iyz="0.000"
        izz="6.60000000E-06" />
    </inertial>
    <visual>
      <origin
        xyz="0 0 0"
        rpy="0 0 0" />
      <geometry>
        <mesh
          filename="./meshes/right_ring_finger_2_pitch.STL" />
      </geometry>
      <material
        name="">
        <color
          rgba="1 1 1 1" />
      </material>
    </visual>
    <collision>
      <origin
        xyz="0 0 0"
        rpy="0 0 0" />
      <geometry>
        <mesh
          filename="./meshes/right_ring_finger_2_pitch.STL" />
      </geometry>
    </collision>
  </link>
  <joint
    name="right_ring_finger_2_pitch"
    type="revolute">
    <origin
      xyz="-0.0112889946629825 -0.149634612145833 0.00354621663087709"
      rpy="-3.03018290398437 1.57071101857885 0.0765032666211449" />
    <parent
      link="right_wrist_yaw" />
    <child
      link="right_ring_finger_2_pitch" />
    <axis
      xyz="0 0 -1" />
    <limit
      lower="0"
      upper="1.58"
      effort="0.5"
      velocity="1.5" />
  </joint>
  <link
    name="right_ring_finger_3_pitch">
    <inertial>
      <origin
        xyz="0.002405 0.021599 0"
        rpy="0 0 0" />
      <mass
        value="0.0189" />
      <inertia
        ixx="2.96700000E-06"
        ixy="6.44000000E-07"
        ixz="0.000"
        iyy="1.02400000E-06"
        iyz="0.000"
        izz="3.12700000E-06" />
    </inertial>
    <visual>
      <origin
        xyz="0 0 0"
        rpy="0 0 0" />
      <geometry>
        <mesh
          filename="./meshes/right_ring_finger_3_pitch.STL" />
      </geometry>
      <material
        name="">
        <color
          rgba="1 1 1 1" />
      </material>
    </visual>
    <collision>
      <origin
        xyz="0 0 0"
        rpy="0 0 0" />
      <geometry>
        <mesh
          filename="./meshes/right_ring_finger_3_pitch.STL" />
      </geometry>
    </collision>
  </link>
  <joint
    name="right_ring_finger_3_pitch"
    type="revolute">
    <origin
      xyz="0 0.0419999999936335 0"
      rpy="0 0 0" />
    <parent
      link="right_ring_finger_2_pitch" />
    <child
      link="right_ring_finger_3_pitch" />
    <axis
      xyz="0 0 -1" />
    <limit
      lower="0"
      upper="1.58"
      effort="0.5"
      velocity="1.5" />
  </joint>
  <link
    name="right_little_finger_2_pitch">
    <inertial>
      <origin
        xyz="-0.000424 0.020629 0"
        rpy="0 0 0" />
      <mass
        value="0.0308" />
      <inertia
        ixx="6.71900000E-06"
        ixy="1.89000000E-07"
        ixz="0.000"
        iyy="2.45000000E-06"
        iyz="0.000"
        izz="6.60000000E-06" />
    </inertial>
    <visual>
      <origin
        xyz="0 0 0"
        rpy="0 0 0" />
      <geometry>
        <mesh
          filename="./meshes/right_little_finger_2_pitch.STL" />
      </geometry>
      <material
        name="">
        <color
          rgba="1 1 1 1" />
      </material>
    </visual>
    <collision>
      <origin
        xyz="0 0 0"
        rpy="0 0 0" />
      <geometry>
        <mesh
          filename="./meshes/right_little_finger_2_pitch.STL" />
      </geometry>
    </collision>
  </link>
  <joint
    name="right_little_finger_2_pitch"
    type="revolute">
    <origin
      xyz="-0.0346341052013609 -0.146952858031617 0.0032932169830828"
      rpy="3.14159265204005 1.57079580738735 -0.0698131716295282" />
    <parent
      link="right_wrist_yaw" />
    <child
      link="right_little_finger_2_pitch" />
    <axis
      xyz="0 0 -1" />
    <limit
      lower="0"
      upper="1.58"
      effort="0.5"
      velocity="1.5" />
  </joint>
  <link
    name="right_little_finger_3_pitch">
    <inertial>
      <origin
        xyz="0.002405 0.021599 0"
        rpy="0 0 0" />
      <mass
        value="0.0189" />
      <inertia
        ixx="2.96700000E-06"
        ixy="6.44000000E-07"
        ixz="0.000"
        iyy="1.02400000E-06"
        iyz="0.000"
        izz="3.12700000E-06" />
    </inertial>
    <visual>
      <origin
        xyz="0 0 0"
        rpy="0 0 0" />
      <geometry>
        <mesh
          filename="./meshes/right_little_finger_3_pitch.STL" />
      </geometry>
      <material
        name="">
        <color
          rgba="1 1 1 1" />
      </material>
    </visual>
    <collision>
      <origin
        xyz="0 0 0"
        rpy="0 0 0" />
      <geometry>
        <mesh
          filename="./meshes/right_little_finger_3_pitch.STL" />
      </geometry>
    </collision>
  </link>
  <joint
    name="right_little_finger_3_pitch"
    type="revolute">
    <origin
      xyz="0 0.0419999999999904 0"
      rpy="0 0 0" />
    <parent
      link="right_little_finger_2_pitch" />
    <child
      link="right_little_finger_3_pitch" />
    <axis
      xyz="0 0 -1" />
    <limit
      lower="0"
      upper="1.58"
      effort="0.5"
      velocity="1.5" />
  </joint>
</robot>